Traceback (most recent call last):
  File "/opt/homebrew/Caskroom/miniforge/base/envs/jupyter-book/lib/python3.8/site-packages/jupyter_cache/executors/utils.py", line 51, in single_nb_execution
    executenb(
  File "/opt/homebrew/Caskroom/miniforge/base/envs/jupyter-book/lib/python3.8/site-packages/nbclient/client.py", line 1112, in execute
    return NotebookClient(nb=nb, resources=resources, km=km, **kwargs).execute()
  File "/opt/homebrew/Caskroom/miniforge/base/envs/jupyter-book/lib/python3.8/site-packages/nbclient/util.py", line 74, in wrapped
    return just_run(coro(*args, **kwargs))
  File "/opt/homebrew/Caskroom/miniforge/base/envs/jupyter-book/lib/python3.8/site-packages/nbclient/util.py", line 53, in just_run
    return loop.run_until_complete(coro)
  File "/opt/homebrew/Caskroom/miniforge/base/envs/jupyter-book/lib/python3.8/asyncio/base_events.py", line 616, in run_until_complete
    return future.result()
  File "/opt/homebrew/Caskroom/miniforge/base/envs/jupyter-book/lib/python3.8/site-packages/nbclient/client.py", line 553, in async_execute
    await self.async_execute_cell(
  File "/opt/homebrew/Caskroom/miniforge/base/envs/jupyter-book/lib/python3.8/site-packages/nbclient/client.py", line 857, in async_execute_cell
    self._check_raise_for_error(cell, exec_reply)
  File "/opt/homebrew/Caskroom/miniforge/base/envs/jupyter-book/lib/python3.8/site-packages/nbclient/client.py", line 760, in _check_raise_for_error
    raise CellExecutionError.from_cell_and_msg(cell, exec_reply_content)
nbclient.exceptions.CellExecutionError: An error occurred while executing the following cell:
------------------
import os
import matplotlib.pyplot as plt
import numpy as np
import pandas as pd

from pathlib import Path
from sqlalchemy import create_engine
from utils.setup import load_env_vars
------------------

[0;31m---------------------------------------------------------------------------[0m
[0;31mModuleNotFoundError[0m                       Traceback (most recent call last)
[0;32m/var/folders/8p/5pp9mtfs287556rfl2mj_rrw0000gn/T/ipykernel_64475/912949105.py[0m in [0;36m<module>[0;34m[0m
[1;32m      6[0m [0;32mfrom[0m [0mpathlib[0m [0;32mimport[0m [0mPath[0m[0;34m[0m[0;34m[0m[0m
[1;32m      7[0m [0;32mfrom[0m [0msqlalchemy[0m [0;32mimport[0m [0mcreate_engine[0m[0;34m[0m[0;34m[0m[0m
[0;32m----> 8[0;31m [0;32mfrom[0m [0mutils[0m[0;34m.[0m[0msetup[0m [0;32mimport[0m [0mload_env_vars[0m[0;34m[0m[0;34m[0m[0m
[0m
[0;31mModuleNotFoundError[0m: No module named 'utils'
ModuleNotFoundError: No module named 'utils'

